<sdf version="1.9">
  <model name="cube_bot">
    <pose>0 0 0.2 0 0 0</pose>

    <!-- BODY -->
    <link name="base_link">
      <inertial>
        <mass>2.0</mass>
      </inertial>

      <collision name="collision">
        <geometry>
          <box><size>0.4 0.4 0.2</size></box>
        </geometry>
      </collision>

      <visual name="visual">
        <geometry>
          <box><size>0.4 0.4 0.2</size></box>
        </geometry>
      </visual>
    </link>

    <!-- LEFT WHEEL -->
    <link name="left_wheel">
      <pose>0 0.2 0 0 0 0</pose>
    </link>

    <!-- RIGHT WHEEL -->
    <link name="right_wheel">
      <pose>0 -0.2 0 0 0 0</pose>
    </link>

    <joint name="left_joint" type="revolute">
      <parent>base_link</parent>
      <child>left_wheel</child>
      <axis><xyz>0 1 0</xyz></axis>
    </joint>

    <joint name="right_joint" type="revolute">
      <parent>base_link</parent>
      <child>right_wheel</child>
      <axis><xyz>0 1 0</xyz></axis>
    </joint>

    <!-- 🔥 Diff Drive -->
    <plugin
  name="gz::sim::systems::DiffDrive"
  filename="gz-sim8-diff-drive-system">

  <left_joint>left_joint</left_joint>
  <right_joint>right_joint</right_joint>

  <wheel_separation>0.4</wheel_separation>
  <wheel_radius>0.05</wheel_radius>

  <!-- control -->
  <topic>/cmd_vel</topic>

  <!-- 🔥 CRITICAL: ENABLE ODOM -->
  <odom_topic>/model/cube_bot/odometry</odom_topic>
  <odom_frame>odom</odom_frame>
  <base_frame>base_link</base_frame>

</plugin>

  </model>
</sdf>