<sdf version="1.9">
  <model name="cube_bot">

    <pose>0 0 0.1 0 0 0</pose>

    <!-- BASE -->
    <link name="base_link">
      <inertial>
        <mass>1.0</mass>
      </inertial>

      <collision name="collision">
        <geometry>
          <box><size>0.3 0.3 0.2</size></box>
        </geometry>
      </collision>

      <visual name="visual">
        <geometry>
          <box><size>0.3 0.3 0.2</size></box>
        </geometry>
      </visual>
    </link>

    <!-- LEFT WHEEL -->
    <link name="left_wheel">
      <pose>0 0.15 0 0 0 0</pose>
    </link>

    <!-- RIGHT WHEEL -->
    <link name="right_wheel">
      <pose>0 -0.15 0 0 0 0</pose>
    </link>

    <!-- JOINTS -->
    <joint name="left_joint" type="revolute">
      <parent>base_link</parent>
      <child>left_wheel</child>
      <axis><xyz>0 1 0</xyz></axis>
    </joint>

    <joint name="right_joint" type="revolute">
      <parent>base_link</parent>
      <child>right_wheel</child>
      <axis><xyz>0 1 0</xyz></axis>
    </joint>

    <!-- ✅ CORRECT DIFF DRIVE -->
    <plugin
        filename="gz-sim-diff-drive-system"
        name="gz::sim::systems::DiffDrive">

      <left_joint>left_joint</left_joint>
      <right_joint>right_joint</right_joint>

      <wheel_separation>0.3</wheel_separation>
      <wheel_radius>0.05</wheel_radius>

      <topic>/model/cube_bot/cmd_vel</topic>

    </plugin>

  </model>
</sdf>